<?xml version="1.0" encoding="utf-8"?>
<!-- =================================================================================== -->
<!-- |    This document was autogenerated by xacro from main.xacro                     | -->
<!-- |    EDITING THIS FILE BY HAND IS NOT RECOMMENDED                                 | -->
<!-- =================================================================================== -->
<robot name="raigor">

  <link name="left_body">
    <inertial>
      <mass value="1"/>
      <inertia ixx="0.0250083333333" ixy="0" ixz="0" iyy="0.0241666666667" iyz="0" izz="0.0425083333333"/>
    </inertial>
    <visual>
      <geometry>
        <!-- <box size="0.4 0.151 0.15"/> -->
        <mesh filename="package://ocs2_robotic_assets/resources/mobile_manipulator/raigor/meshes/vehicle/track_entity_meter.STL"/>
      </geometry>
    </visual>
    <collision>
      <geometry>
        <box size="0.4 0.151 0.15"/>
      </geometry>
    </collision>
  </link>
  <link name="right_body">
    <inertial>
      <mass value="1"/>
      <inertia ixx="0.0250083333333" ixy="0" ixz="0" iyy="0.0241666666667" iyz="0" izz="0.0425083333333"/>
    </inertial>
    <visual>
      <geometry>
        <!-- <box size="0.4 0.151 0.15"/> -->
        <mesh filename="package://ocs2_robotic_assets/resources/mobile_manipulator/raigor/meshes/vehicle/track_entity_meter.STL"/>
      </geometry>
    </visual>
    <collision>
      <geometry>
        <box size="0.4 0.151 0.15"/>
      </geometry>
    </collision>
  </link>


  <link name="arm_body">
    <inertial>
      <mass value="0.3"/>
      <inertia ixx="0.0250083333333" ixy="0" ixz="0" iyy="0.0241666666667" iyz="0" izz="0.0425083333333"/>
    </inertial>
    <visual>
      <geometry>
        <box size="0.375 0.18 0.11"/>
      </geometry>
    </visual>
    <collision>
      <geometry>
        <box size="0.375 0.18 0.11"/>
      </geometry>
    </collision>
  </link>
  <link name="arm_connector">
    <inertial>
      <mass value="0.2"/>
      <!-- assuming axis of cylinder is y, not z -->
      <inertia ixx="0.004655" ixy="0" ixz="0" iyy="0.00064" iyz="0" izz="0.004655"/>
    </inertial>
    <visual>
      <origin rpy="1.57079632679 0 0" xyz="0 0 0"/>
      <geometry>
        <cylinder length="0.25" radius="0.035"/>
      </geometry>
    </visual>
    <collision>
      <origin rpy="1.57079632679 0 0" xyz="0 0 0"/>
      <geometry>
        <cylinder length="0.25" radius="0.035"/>
      </geometry>
    </collision>
  </link>
  <joint name="arm_connector_joint" type="fixed">
    <origin rpy="0 0 0" xyz="-0.188 0 0"/>
    <parent link="arm_connector"/>
    <child link="arm_body"/>
    <axis xyz="0 1 0"/>
  </joint>


  <link name="vehicle_base_link">
    <inertial>
      <mass value="150"/>
      <inertia ixx="15.75125" ixy="0" ixz="0" iyy="15.625" iyz="0" izz="6.37625"/>
    </inertial>
    <visual>
      <geometry>
        <!-- <box size="0.4 0.4 0.1" /> -->
        <mesh filename="package://ocs2_robotic_assets/resources/mobile_manipulator/raigor/meshes/vehicle/base_meter.STL"/>
      </geometry>
    </visual>
    <collision>
      <geometry>
        <!-- <box size="0.4 0.4 0.1" /> -->
        <mesh filename="package://ocs2_robotic_assets/resources/mobile_manipulator/raigor/meshes/vehicle/base_meter.STL"/>
      </geometry>
    </collision>
  </link>
  <joint name="left_track_joint" type="fixed">
    <origin rpy="0 0 0" xyz="0 0.287 0"/>
    <parent link="vehicle_base_link"/>
    <child link="left_body"/>
  </joint>
  <joint name="right_track_joint" type="fixed">
    <origin rpy="0 0 0" xyz="0 -0.287 0"/>
    <parent link="vehicle_base_link"/>
    <child link="right_body"/>
  </joint>
  <link name="pusher_visual_left">
    <inertial>
      <mass value="1"/>
      <inertia ixx="0.105008333333" ixy="0" ixz="0" iyy="0.104166666667" iyz="0" izz="0.0425083333333"/>
    </inertial>
    <visual>
      <geometry>
        <box size="0.5 0.025  0.08"/>
      </geometry>
    </visual>
    <collision>
      <geometry>
        <box size="0.5 0.025  0.08"/>
      </geometry>
    </collision>
  </link>
  <link name="pusher_visual_right">
    <inertial>
      <mass value="1"/>
      <inertia ixx="0.105008333333" ixy="0" ixz="0" iyy="0.104166666667" iyz="0" izz="0.0425083333333"/>
    </inertial>
    <visual>
      <geometry>
        <box size="0.5 0.025  0.08"/>
      </geometry>
    </visual>
    <collision>
      <geometry>
        <box size="0.5 0.025 0.08"/>
      </geometry>
    </collision>
  </link>
  <joint name="pusher_visual_left_joint" type="fixed">
    <origin rpy="0 0 0" xyz="-0.27 0.12 0"/>
    <parent link="vehicle_base_link"/>
    <child link="pusher_visual_left"/>
  </joint>
  <joint name="pusher_visual_right_joint" type="fixed">
    <origin rpy="0 0 0" xyz="-0.27 -0.12 0"/>
    <parent link="vehicle_base_link"/>
    <child link="pusher_visual_right"/>
  </joint>

  <joint name="push_plate_joint" type="fixed">
    <origin rpy="0 0 0" xyz="-0.479 0 0"/>
    <parent link="vehicle_base_link"/>
    <child link="arm_connector"/>
    <axis xyz="0 1 0"/>
  </joint>


  <link name="base_link">
    <visual>
      <geometry>
        <mesh filename="package://ocs2_robotic_assets/resources/mobile_manipulator/raigor/meshes/ur5e/visual/base.dae"/>
      </geometry>
      <material name="LightGrey">
        <color rgba="0.7 0.7 0.7 1.0"/>
      </material>
    </visual>
    <collision>
      <geometry>
        <mesh filename="package://ocs2_robotic_assets/resources/mobile_manipulator/raigor/meshes/ur5e/collision/base.stl"/>
      </geometry>
    </collision>
    <inertial>
      <mass value="4.0"/>
      <origin rpy="0 0 0" xyz="0.0 0.0 0.0"/>
      <inertia ixx="0.00443333156" ixy="0.0" ixz="0.0" iyy="0.00443333156" iyz="0.0" izz="0.0072"/>
    </inertial>
  </link>
  <joint name="shoulder_pan_joint" type="revolute">
    <parent link="base_link"/>
    <child link="shoulder_link"/>
    <origin rpy="0.0 0.0 0.0" xyz="0.0 0.0 0.163"/>
    <axis xyz="0 0 1"/>
    <limit effort="150.0" lower="-6.28318530718" upper="6.28318530718" velocity="3.14"/>
    <dynamics damping="0.0" friction="0.0"/>
  </joint>
  <link name="shoulder_link">
    <visual>
      <geometry>
        <mesh filename="package://ocs2_robotic_assets/resources/mobile_manipulator/raigor/meshes/ur5e/visual/shoulder.dae"/>
      </geometry>
      <material name="LightGrey">
        <color rgba="0.7 0.7 0.7 1.0"/>
      </material>
    </visual>
    <collision>
      <geometry>
        <mesh filename="package://ocs2_robotic_assets/resources/mobile_manipulator/raigor/meshes/ur5e/collision/shoulder.stl"/>
      </geometry>
    </collision>
    <inertial>
      <mass value="3.7"/>
      <origin rpy="0 0 0" xyz="0.0 0.0 0.0"/>
      <inertia ixx="0.010267495893" ixy="0.0" ixz="0.0" iyy="0.010267495893" iyz="0.0" izz="0.00666"/>
    </inertial>
  </link>
  <joint name="shoulder_lift_joint" type="revolute">
    <parent link="shoulder_link"/>
    <child link="upper_arm_link"/>
    <origin rpy="0.0 1.57079632679 0.0" xyz="0.0 0.138 0.0"/>
    <axis xyz="0 1 0"/>
    <limit effort="150.0" lower="-6.28318530718" upper="6.28318530718" velocity="3.14"/>
    <dynamics damping="0.0" friction="0.0"/>
  </joint>
  <link name="upper_arm_link">
    <visual>
      <geometry>
        <mesh filename="package://ocs2_robotic_assets/resources/mobile_manipulator/raigor/meshes/ur5e/visual/upperarm.dae"/>
      </geometry>
      <material name="LightGrey">
        <color rgba="0.7 0.7 0.7 1.0"/>
      </material>
    </visual>
    <collision>
      <geometry>
        <mesh filename="package://ocs2_robotic_assets/resources/mobile_manipulator/raigor/meshes/ur5e/collision/upperarm.stl"/>
      </geometry>
    </collision>
    <inertial>
      <mass value="8.393"/>
      <origin rpy="0 0 0" xyz="0.0 0.0 0.2125"/>
      <inertia ixx="0.133885781862" ixy="0.0" ixz="0.0" iyy="0.133885781862" iyz="0.0" izz="0.0151074"/>
    </inertial>
  </link>
  <joint name="elbow_joint" type="revolute">
    <parent link="upper_arm_link"/>
    <child link="forearm_link"/>
    <origin rpy="0.0 0.0 0.0" xyz="0.0 -0.131 0.425"/>
    <axis xyz="0 1 0"/>
    <limit effort="150.0" lower="-3.14159265359" upper="3.14159265359" velocity="3.14"/>
    <dynamics damping="0.0" friction="0.0"/>
  </joint>
  <link name="forearm_link">
    <visual>
      <geometry>
        <mesh filename="package://ocs2_robotic_assets/resources/mobile_manipulator/raigor/meshes/ur5e/visual/forearm.dae"/>
      </geometry>
      <material name="LightGrey">
        <color rgba="0.7 0.7 0.7 1.0"/>
      </material>
    </visual>
    <collision>
      <geometry>
        <mesh filename="package://ocs2_robotic_assets/resources/mobile_manipulator/raigor/meshes/ur5e/collision/forearm.stl"/>
      </geometry>
    </collision>
    <inertial>
      <mass value="2.275"/>
      <origin rpy="0 0 0" xyz="0.0 0.0 0.196"/>
      <inertia ixx="0.0311796208615" ixy="0.0" ixz="0.0" iyy="0.0311796208615" iyz="0.0" izz="0.004095"/>
    </inertial>
  </link>
  <joint name="wrist_1_joint" type="revolute">
    <parent link="forearm_link"/>
    <child link="wrist_1_link"/>
    <origin rpy="0.0 1.57079632679 0.0" xyz="0.0 0.0 0.392"/>
    <axis xyz="0 1 0"/>
    <limit effort="28.0" lower="-6.28318530718" upper="6.28318530718" velocity="6.28"/>
    <dynamics damping="0.0" friction="0.0"/>
  </joint>
  <link name="wrist_1_link">
    <visual>
      <geometry>
        <mesh filename="package://ocs2_robotic_assets/resources/mobile_manipulator/raigor/meshes/ur5e/visual/wrist1.dae"/>
      </geometry>
      <material name="LightGrey">
        <color rgba="0.7 0.7 0.7 1.0"/>
      </material>
    </visual>
    <collision>
      <geometry>
        <mesh filename="package://ocs2_robotic_assets/resources/mobile_manipulator/raigor/meshes/ur5e/collision/wrist1.stl"/>
      </geometry>
    </collision>
    <inertial>
      <mass value="1.219"/>
      <origin rpy="0 0 0" xyz="0.0 0.127 0.0"/>
      <inertia ixx="0.00255989897604" ixy="0.0" ixz="0.0" iyy="0.00255989897604" iyz="0.0" izz="0.0021942"/>
    </inertial>
  </link>
  <joint name="wrist_2_joint" type="revolute">
    <parent link="wrist_1_link"/>
    <child link="wrist_2_link"/>
    <origin rpy="0.0 0.0 0.0" xyz="0.0 0.127 0.0"/>
    <axis xyz="0 0 1"/>
    <limit effort="28.0" lower="-6.28318530718" upper="6.28318530718" velocity="6.28"/>
    <dynamics damping="0.0" friction="0.0"/>
  </joint>
  <link name="wrist_2_link">
    <visual>
      <geometry>
        <mesh filename="package://ocs2_robotic_assets/resources/mobile_manipulator/raigor/meshes/ur5e/visual/wrist2.dae"/>
      </geometry>
      <material name="LightGrey">
        <color rgba="0.7 0.7 0.7 1.0"/>
      </material>
    </visual>
    <collision>
      <geometry>
        <mesh filename="package://ocs2_robotic_assets/resources/mobile_manipulator/raigor/meshes/ur5e/collision/wrist2.stl"/>
      </geometry>
    </collision>
    <inertial>
      <mass value="1.219"/>
      <origin rpy="0 0 0" xyz="0.0 0.0 0.1"/>
      <inertia ixx="0.00255989897604" ixy="0.0" ixz="0.0" iyy="0.00255989897604" iyz="0.0" izz="0.0021942"/>
    </inertial>
  </link>
  <joint name="wrist_3_joint" type="revolute">
    <parent link="wrist_2_link"/>
    <child link="wrist_3_link"/>
    <origin rpy="0.0 0.0 0.0" xyz="0.0 0.0 0.1"/>
    <axis xyz="0 1 0"/>
    <limit effort="28.0" lower="-6.28318530718" upper="6.28318530718" velocity="6.28"/>
    <dynamics damping="0.0" friction="0.0"/>
  </joint>
  <link name="wrist_3_link">
    <visual>
      <geometry>
        <mesh filename="package://ocs2_robotic_assets/resources/mobile_manipulator/raigor/meshes/ur5e/visual/wrist3.dae"/>
      </geometry>
      <material name="LightGrey">
        <color rgba="0.7 0.7 0.7 1.0"/>
      </material>
    </visual>
    <collision>
      <geometry>
        <mesh filename="package://ocs2_robotic_assets/resources/mobile_manipulator/raigor/meshes/ur5e/collision/wrist3.stl"/>
      </geometry>
    </collision>
    <inertial>
      <mass value="0.1879"/>
      <origin rpy="1.57079632679 0 0" xyz="0.0 0.0771 0.0"/>
      <inertia ixx="9.89041005217e-05" ixy="0.0" ixz="0.0" iyy="9.89041005217e-05" iyz="0.0" izz="0.0001321171875"/>
    </inertial>
  </link>
  <joint name="ee_fixed_joint" type="fixed">
    <parent link="wrist_3_link"/>
    <child link="ee_link"/>
    <origin rpy="0.0 0.0 1.57079632679" xyz="0.0 0.1 0.0"/>
  </joint>
  <link name="ee_link">
    <collision>
      <geometry>
        <box size="0.01 0.01 0.01"/>
      </geometry>
      <origin rpy="0 0 0" xyz="-0.01 0 0"/>
    </collision>
  </link>


  <link name="board_link">
    <origin rpy="0 0 0" xyz="0.0 0.0 0.0"/>
    <visual>
      <geometry>
        <mesh filename="package://ocs2_robotic_assets/resources/mobile_manipulator/raigor/meshes/vehicle/board_link.STL"/>
      </geometry>
    </visual>
    <collision>
      <geometry>
        <mesh filename="package://ocs2_robotic_assets/resources/mobile_manipulator/raigor/meshes/vehicle/board_link.STL"/>
      </geometry>
    </collision>
  </link>

  <link name="lidar_support_link">
    <origin rpy="-3.14 0 0" xyz="0.0 0.0 0.0"/>
    <visual>
      <geometry>
        <mesh filename="package://ocs2_robotic_assets/resources/mobile_manipulator/raigor/meshes/vehicle/lidar_support.STL"/>
      </geometry>
    </visual>
    <collision>
      <geometry>
        <mesh filename="package://ocs2_robotic_assets/resources/mobile_manipulator/raigor/meshes/vehicle/lidar_support.STL"/>
      </geometry>
    </collision>
  </link>

  <joint name="board_joint" type="fixed">
    <origin rpy="0 0 0" xyz="-0.055 0 0.32"/>
    <parent link="vehicle_base_link"/>
    <child link="board_link"/>
  </joint>

  <joint name="lidar_support_joint" type="fixed">
    <origin rpy="0 0 0" xyz="-0.05 0.0 0.48"/>
    <parent link="vehicle_base_link"/>
    <child link="lidar_support_link"/>
  </joint>

  <link name="laser_link">
    <inertial>
      <mass value="0.1"/>
      <origin xyz="0 0 0"/>
      <inertia ixx="0.01" ixy="0.0" ixz="0.0" iyy="0.01" iyz="0.0" izz="0.01"/>
    </inertial>
    <visual>
      <origin rpy="0 0 0" xyz=" 0 0 0 "/>
      <geometry>
        <cylinder length="0.05" radius="0.05"/>
      </geometry>
      <material name="black"/>
    </visual>
    <collision>
      <origin rpy="0 0 0" xyz="0.0 0.0 0.0"/>
      <geometry>
        <cylinder length="0.06" radius="0.05"/>
      </geometry>
    </collision>
  </link>

  <joint name="laser_support_joint" type="fixed">
    <origin rpy="0 0 0" xyz="0.0 0.0 0.02"/>
    <parent link="lidar_support_link"/>
    <child link="laser_link"/>
  </joint>

  <joint name="associate_joint" type="fixed">
    <origin rpy="0 0 -1.57" xyz="0.365 0 0.28"/>
    <parent link="vehicle_base_link"/>
    <child link="base_link"/>
  </joint>

</robot>